Workbook

Sheet Leia-me
A1: Lista das imagens usadas no artigo do açaí (banco final do YOLO, 547 imagens)
A3: Aba "Imagens": uma linha por imagem do banco final, com a partição usada no treino final (divisão por imagem de origem, semente 42).
A4: Origem: iNaturalist (472), busca na internet de açaí (29), imagens originais do grupo vindas da internet (42) e geradas por IA (4).
A5: As 46 imagens originais (42 + 4 de IA) são as mesmas dos experimentos preliminares.
A6: Imagens iNaturalist: link da observação, link da foto, autor, licença e atribuição vêm da API do iNaturalist (observações com grau de pesquisa).
A7: "É triatomíneo?" = Não: inseto parecido (Reduviidae ou Coreidae não triatomíneo) mantido como imagem de fundo, sem marcação.
A8: Células amarelas: a preencher pelo grupo (link de origem, autor e licença das imagens da internet). Usem a busca reversa do Google Lens.
A9: Links marcados como "provável" foram deduzidos do nome do arquivo e precisam ser conferidos.
A11: Atenção: imagens de terceiros não devem ser redistribuídas. Esta lista pode ir como material suplementar; os arquivos de imagem não.
A12: A aba "Resumo" usa fórmulas e se atualiza quando a aba "Imagens" for editada.

Sheet Imagens
A1: Nº | B1: Arquivo no banco final | C1: Origem | D1: Partição | E1: Conteúdo | F1: Instâncias açaí | G1: Instâncias triatomíneo | H1: Grupo da busca | I1: Táxon registrado | J1: É triatomíneo? | K1: ID observação iNaturalist | L1: Link da observação | M1: Link da foto | N1: Autor (usuário) | O1: Licença | P1: Atribuição | Q1: Data da observação | R1: Latitude | S1: Longitude | T1: Link de origem (web) | U1: Notas
A2: 1 | B2: A_ANOTAR-BARBEIRO__inat_100102394_167027133_jpg_jpg.rf.583723a4947f6999e0f0beb84bd4ac90.jpg | C2: iNaturalist | D2: Treino | E2: triatomíneo | F2: 0 | G2: 1 | H2: Triatomíneos (Brasil) | I2: Panstrongylus megistus | J2: Sim | K2: 100102394 | L2: https://www.inaturalist.org/observations/100102394 | M2: https://inaturalist-open-data.s3.amazonaws.com/photos/167027133/large.jpeg | N2: joanapereira | O2: CC-BY-NC | P2: (c) Joana Pereira, some rights reserved (CC BY-NC) | Q2: 2021-10-30 | R2: -19.50951 | S2: -43.91022
A3: 2 | B3: A_ANOTAR-BARBEIRO__inat_103266290_172789283_jpg_jpg.rf.a65605525592f434380d00428ca0a9c0.jpg | C3: iNaturalist | D3: Teste | E3: triatomíneo | F3: 0 | G3: 1 | H3: Triatomíneos (Brasil) | I3: Panstrongylus megistus | J3: Sim | K3: 103266290 | L3: https://www.inaturalist.org/observations/103266290 | M3: https://inaturalist-open-data.s3.amazonaws.com/photos/172789283/large.jpg | N3: rodrigodios | O3: CC-BY-NC | P3: (c) Rodrigo Dios, some rights reserved (CC BY-NC) | Q3: 2021-12-18 | R3: -23.63827 | S3: -46.70445
A4: 3 | B4: A_ANOTAR-BARBEIRO__inat_134950462_230111835_jpg_jpg.rf.478a936da1ef1b1b10afc4245adc9e6f.jpg | C4: iNaturalist | D4: Treino | E4: triatomíneo | F4: 0 | G4: 1 | H4: Triatomíneos (Brasil) | I4: Panstrongylus megistus | J4: Sim | K4: 134950462 | L4: https://www.inaturalist.org/observations/134950462 | M4: https://inaturalist-open-data.s3.amazonaws.com/photos/230111835/large.jpg | N4: luisacostan | O4: CC-BY-NC | P4: (c) luisacostan, some rights reserved (CC BY-NC) | Q4: 2020-07-14 | R4: -15.82143 | S4: -48.06865
A5: 4 | B5: A_ANOTAR-BARBEIRO__inat_145619336_250163578_jpg_jpg.rf.13a12c8bb53e76ff40783ca1c26991d6.jpg | C5: iNaturalist | D5: Teste | E5: triatomíneo | F5: 0 | G5: 1 | H5: Triatomíneos (Brasil) | I5: Panstrongylus megistus | J5: Sim | K5: 145619336 | L5: https://www.inaturalist.org/observations/145619336 | M5: https://inaturalist-open-data.s3.amazonaws.com/photos/250163578/large.jpeg | N5: gnomecannon | O5: CC-BY-NC | P5: (c) gnomecannon, some rights reserved (CC BY-NC) | Q5: 2022-12-24 | R5: -29.84738 | S5: -51.08977
A6: 5 | B6: A_ANOTAR-BARBEIRO__inat_147334496_253507764_jpg_jpg.rf.62f5af0692b54984cc3405ae6b37f6ec.jpg | C6: iNaturalist | D6: Teste | E6: triatomíneo | F6: 0 | G6: 1 | H6: Triatomíneos (Brasil) | I6: Panstrongylus megistus | J6: Sim | K6: 147334496 | L6: https://www.inaturalist.org/observations/147334496 | M6: https://inaturalist-open-data.s3.amazonaws.com/photos/253507764/large.jpg | N6: jaderredtax | O6: CC-BY-NC | P6: (c) Jader de Oliveira, some rights reserved (CC BY-NC) | Q6: 2020-12-05 | R6: -19.76033 | S6: -43.63464
A7: 6 | B7: A_ANOTAR-BARBEIRO__inat_147494511_253809445_jpg_jpg.rf.63b65ce21346c976d0207c23d1dec17b.jpg | C7: iNaturalist | D7: Treino | E7: triatomíneo | F7: 0 | G7: 1 | H7: Triatomíneos (Brasil) | I7: Panstrongylus megistus | J7: Sim | K7: 147494511 | L7: https://www.inaturalist.org/observations/147494511 | M7: https://inaturalist-open-data.s3.amazonaws.com/photos/253809445/large.jpg | N7: jaderredtax | O7: CC-BY-NC | P7: (c) Jader de Oliveira, some rights reserved (CC BY-NC) | Q7: 2023-01-27 | R7: -23.68799 | S7: -46.62518
A8: 7 | B8: A_ANOTAR-BARBEIRO__inat_147720188_254238221_jpg_jpg.rf.ca0476324bccbdfa7c730c482781c988.jpg | C8: iNaturalist | D8: Treino | E8: triatomíneo | F8: 0 | G8: 1 | H8: Triatomíneos (Brasil) | I8: Panstrongylus megistus | J8: Sim | K8: 147720188 | L8: https://www.inaturalist.org/observations/147720188 | M8: https://inaturalist-open-data.s3.amazonaws.com/photos/254238221/large.jpg | N8: jaderredtax | O8: CC-BY-NC | P8: (c) Jader de Oliveira, some rights reserved (CC BY-NC) | Q8: 2021-11-05 | R8: -19.58518 | S8: -46.9448
A9: 8 | B9: A_ANOTAR-BARBEIRO__inat_147720287_254238336_jpg_jpg.rf.b2ce6f5b482b1669a4806041412c8694.jpg | C9: iNaturalist | D9: Treino | E9: triatomíneo | F9: 0 | G9: 1 | H9: Triatomíneos (Brasil) | I9: Triatoma vitticeps | J9: Sim | K9: 147720287 | L9: https://www.inaturalist.org/observations/147720287 | M9: https://inaturalist-open-data.s3.amazonaws.com/photos/254238336/large.jpg | N9: jaderredtax | O9: CC-BY-NC | P9: (c) Jader de Oliveira, some rights reserved (CC BY-NC) | Q9: 2021-09-22 | R9: -20.36257 | S9: -40.65821
A10: 9 | B10: A_ANOTAR-BARBEIRO__inat_147767770_254327908_jpg_jpg.rf.b91aaea228a38ed425c9a1207ecaa271.jpg | C10: iNaturalist | D10: Teste | E10: triatomíneo | F10: 0 | G10: 2 | H10: Triatomíneos (Brasil) | I10: Panstrongylus megistus | J10: Sim | K10: 147767770 | L10: https://www.inaturalist.org/observations/147767770 | M10: https://inaturalist-open-data.s3.amazonaws.com/photos/254327908/large.jpg | N10: jaderredtax | O10: CC-BY-NC | P10: (c) Jader de Oliveira, some rights reserved (CC BY-NC) | Q10: 2023-01-25 | R10: -19.74604 | S10: -47.93399
A11: 10 | B11: A_ANOTAR-BARBEIRO__inat_147841371_254470418_jpg_jpg.rf.acd2c240dcfb07d85473bacfbf989323.jpg | C11: iNaturalist | D11: Treino | E11: triatomíneo | F11: 0 | G11: 1 | H11: Triatomíneos (Brasil) | I11: Triatoma vitticeps | J11: Sim | K11: 147841371 | L11: https://www.inaturalist.org/observations/147841371 | M11: https://inaturalist-open-data.s3.amazonaws.com/photos/254470418/large.jpeg | N11: jaderredtax | O11: CC-BY-NC | P11: (c) Jader de Oliveira, some rights reserved (CC BY-NC) | Q11: 2023-01-31 | R11: -21.02918 | S11: -41.65513
A12: 11 | B12: A_ANOTAR-BARBEIRO__inat_148013142_254804610_jpg_jpg.rf.6d10fea47ca23ae1e8f6f9f60a78abeb.jpg | C12: iNaturalist | D12: Treino | E12: triatomíneo | F12: 0 | G12: 1 | H12: Triatomíneos (Brasil) | I12: Panstrongylus lutzi | J12: Sim | K12: 148013142 | L12: https://www.inaturalist.org/observations/148013142 | M12: https://inaturalist-open-data.s3.amazonaws.com/photos/254804610/large.jpeg | N12: akarena | O12: CC-BY-NC | P12: (c) akarena, some rights reserved (CC BY-NC) | Q12: 2023-02-03 | R12: -6.84314 | S12: -35.53059
A13: 12 | B13: A_ANOTAR-BARBEIRO__inat_163244385_282329663_jpg_jpg.rf.20fe852e98eb1ea8716cfda4a8778427.jpg | C13: iNaturalist | D13: Treino | E13: triatomíneo | F13: 0 | G13: 1 | H13: Triatomíneos (Brasil) | I13: Triatoma sordida | J13: Sim | K13: 163244385 | L13: https://www.inaturalist.org/observations/163244385 | M13: https://inaturalist-open-data.s3.amazonaws.com/photos/282329663/large.jpeg | N13: adriano_dias_amaro | O13: CC-BY-NC | P13: (c) Adriano Dias Amaro, some rights reserved (CC BY-NC) | Q13: 2023-05-22 | R13: -16.42161 | S13: -54.6243
... A473: 472 | B473: inat_93956626_155796713_jpg_jpg.rf.d4b90697be7c4df61d725edd9c64937a.jpg | C473: iNaturalist | D473: Treino | E473: triatomíneo | F473: 0 | G473: 1 | H473: Triatomíneos (Brasil) | I473: Rhodnius robustus | J473: Sim | K473: 93956626 | L473: https://www.inaturalist.org/observations/93956626 | M473: https://inaturalist-open-data.s3.amazonaws.com/photos/155796713/large.jpeg | N473: flsantos | O473: CC-BY-NC | P473: (c) Fábio Luis dos Santos, some rights reserved (CC BY-NC) | Q473: 2021-09-05 | R473: -9.85972 | S473: -56.06778
A474: 473 | B474: web_acai_01_jpg.rf.2c3ccf3b3f4d35f9f1329eddf262797b.jpg | C474: Busca na internet (açaí) | D474: Validação | E474: açaí | F474: 1 | G474: 0 | H474: Euterpe oleracea | I474: Euterpe oleracea | J474: Não se aplica | U474: Busca no Google; arquivo original: A#U00e7ai1.jpg
A475: 474 | B475: web_acai_02_jpg.rf.ef3243f0aaa2f8c15ce2cdec2e525f12.jpg | C475: Busca na internet (açaí) | D475: Teste | E475: açaí | F475: 2 | G475: 0 | H475: Euterpe oleracea | I475: Euterpe oleracea | J475: Não se aplica | U475: Busca no Google; arquivo original: a#U00e7ai 1.jpeg
A476: 475 | B476: web_acai_03_jpg.rf.14d67a51d9a6189398b803677d6264ef.jpg | C476: Busca na internet (açaí) | D476: Treino | E476: açaí | F476: 3 | G476: 0 | H476: Euterpe oleracea | I476: Euterpe oleracea | J476: Não se aplica | U476: Busca no Google; arquivo original: a#U00e7ai.jpeg
A477: 476 | B477: web_acai_04_jpg.rf.1b689e548674354d18b0a04f0a8d817b.jpg | C477: Busca na internet (açaí) | D477: Treino | E477: açaí | F477: 2 | G477: 0 | H477: Euterpe oleracea | I477: Euterpe oleracea | J477: Não se aplica | U477: Busca no Google; arquivo original: a#U00e7ai2.jpeg
A478: 477 | B478: web_acai_05_jpg.rf.a279ec63579411fd2db272c80bda8cf3.jpg | C478: Busca na internet (açaí) | D478: Treino | E478: açaí | F478: 1 | G478: 0 | H478: Euterpe oleracea | I478: Euterpe oleracea | J478: Não se aplica | U478: Busca no Google; arquivo original: acai (1).webp
A479: 478 | B479: web_acai_08_jpg.rf.ea63749294b54d9d3e7aca635f521d11.jpg | C479: Busca na internet (açaí) | D479: Validação | E479: açaí | F479: 1 | G479: 0 | H479: Euterpe oleracea | I479: Euterpe oleracea | J479: Não se aplica | U479: Busca no Google; arquivo original: acai 12.jpg
A480: 479 | B480: web_acai_09_jpg.rf.f3beed6c43ab21abd6962c668662ce1d.jpg | C480: Busca na internet (açaí) | D480: Treino | E480: açaí | F480: 1 | G480: 0 | H480: Euterpe oleracea | I480: Euterpe oleracea | J480: Não se aplica | U480: Busca no Google; arquivo original: acai 13.jpeg
A481: 480 | B481: web_acai_10_jpg.rf.95eef587100b1ac81379f01fac6471b5.jpg | C481: Busca na internet (açaí) | D481: Teste | E481: açaí | F481: 1 | G481: 0 | H481: Euterpe oleracea | I481: Euterpe oleracea | J481: Não se aplica | U481: Busca no Google; arquivo original: acai 14.jpeg
A482: 481 | B482: web_acai_11_jpg.rf.4ef8560b48d0634a3cdb94098a0f0fae.jpg | C482: Busca na internet (açaí) | D482: Treino | E482: açaí | F482: 1 | G482: 0 | H482: Euterpe oleracea | I482: Euterpe oleracea | J482: Não se aplica | U482: Busca no Google; arquivo original: acai 15.jpg
A483: 482 | B483: web_acai_14_jpg.rf.2ddac7c26552f892a840f1774d8f1c50.jpg | C483: Busca na internet (açaí) | D483: Treino | E483: açaí | F483: 2 | G483: 0 | H483: Euterpe oleracea | I483: Euterpe oleracea | J483: Não se aplica | U483: Busca no Google; arquivo original: acai 19.jpeg
A484: 483 | B484: web_acai_15_jpg.rf.505039ac5637ac7526833c423b9125a8.jpg | C484: Busca na internet (açaí) | D484: Treino | E484: açaí | F484: 2 | G484: 0 | H484: Euterpe oleracea | I484: Euterpe oleracea | J484: Não se aplica | U484: Busca no Google; arquivo original: acai 20.webp
A485: 484 | B485: web_acai_16_jpg.rf.ac0c2b8e99d5635265a4b43dedb7f34c.jpg | C485: Busca na internet (açaí) | D485: Treino | E485: açaí | F485: 1 | G485: 0 | H485: Euterpe oleracea | I485: Euterpe oleracea | J485: Não se aplica | U485: Busca no Google; arquivo original: acai 21.jpeg
... A501: 500 | B501: web_acai_42_jpg.rf.c7a4923d629a5a37b2f01fdff86b6966.jpg | C501: Busca na internet (açaí) | D501: Treino | E501: açaí | F501: 3 | G501: 0 | H501: Euterpe oleracea | I501: Euterpe oleracea | J501: Não se aplica | U501: Busca no Google; arquivo original: imagem-de-uma-palmeira-euterpe-oleracea-com-folhas.webp
A502: 501 | B502: web_acai_43_jpg.rf.37c6c7146eca911773629a7b75545e19.jpg | C502: Busca na internet (açaí) | D502: Treino | E502: açaí | F502: 1 | G502: 0 | H502: Euterpe oleracea | I502: Euterpe oleracea | J502: Não se aplica | T502: https://www.pexels.com/photo/6741479/ | U502: Busca no Google; arquivo original: pexels-photo-6741479_c275a620-7953-4bd3-b64d-e43ca308a1dd_1000x.jpg; provável Pexels (conferir)
A503: 502 | B503: 01EG741_jpg_jpg.rf.df1656e78aacf776046e7b7100872a44.jpg | C503: Original do grupo (internet) | D503: Treino | E503: açaí | F503: 3 | G503: 0 | U503: Procurar a origem por busca reversa (Google Lens)
A504: 503 | B504: 151480040m_jpg_jpg.rf.e0e9a3615087087f20b68f145e7b888d.jpg | C504: Original do grupo (internet) | D504: Teste | E504: açaí | F504: 1 | G504: 0 | U504: Procurar a origem por busca reversa (Google Lens)
A505: 504 | B505: 1703774866658d8a92ec56e_jpg_jpg.rf.81b5425232edee663431b38ab97c118b.jpg | C505: Original do grupo (internet) | D505: Treino | E505: açaí | F505: 1 | G505: 0 | U505: Procurar a origem por busca reversa (Google Lens)
A506: 505 | B506: 1_interna_1_foto_peter_ilicciev_fiocruz-6251156_webp_jpg.rf.3c12c6835bd008d1b86f50ca4f24acf0.jpg | C506: Original do grupo (internet) | D506: Treino | E506: triatomíneo | F506: 0 | G506: 1 | U506: Foto Peter Ilicciev / Fiocruz
A507: 506 | B507: 287490_jpg_jpg.rf.28c9bfaaa006e337da6e92f5335f264a.jpg | C507: Original do grupo (internet) | D507: Treino | E507: triatomíneo | F507: 0 | G507: 1 | U507: Procurar a origem por busca reversa (Google Lens)
A508: 507 | B508: 5cae37ff-1ab2-4c5b-9894-4f04757d3547_jpeg_jpg.rf.d2c816a2de620d011c5626f657e46075.jpg | C508: Original do grupo (internet) | D508: Teste | E508: triatomíneo | F508: 0 | G508: 1 | U508: Procurar a origem por busca reversa (Google Lens)
A509: 508 | B509: Barbeiro-1024x668_jpeg_jpg.rf.441648fef85570ff550b0c7f795121dd.jpg | C509: Original do grupo (internet) | D509: Teste | E509: triatomíneo | F509: 0 | G509: 1 | U509: Procurar a origem por busca reversa (Google Lens)
A510: 509 | B510: Captura-de-tela-2023-12-19-143337_webp_jpg.rf.3b8fb6b02e8894d0528957ecf16ac4a6.jpg | C510: Original do grupo (internet) | D510: Teste | E510: açaí | F510: 1 | G510: 0 | U510: Procurar a origem por busca reversa (Google Lens)
A511: 510 | B511: Idam-acai-Foto-Divulgacao-Idam-1024x683_jpg_jpg.rf.10148caaa720700dc0e92678f9911acd.jpg | C511: Original do grupo (internet) | D511: Treino | E511: açaí | F511: 1 | G511: 0 | U511: Foto de divulgação do Idam (Amazonas)
A512: 511 | B512: Os_Segredos_do_Inseto_Barbeiro_02_png_jpg.rf.1d8ae283134f3f463e12863ee9f0c413.jpg | C512: Original do grupo (internet) | D512: Teste | E512: triatomíneo | F512: 0 | G512: 1 | U512: Procurar a origem por busca reversa (Google Lens)
A513: 512 | B513: WhatsApp-Image-2026-07-03-at-11-27-09_jpeg_jpg.rf.c55e15fa865b1f583ff7fe4bb866c2f0.jpg | C513: Original do grupo (internet) | D513: Treino | E513: açaí, triatomíneo | F513: 1 | G513: 1 | U513: Recebida pelo WhatsApp do grupo; procurar a origem por busca reversa (Google Lens)
A514: 513 | B514: WhatsApp-Image-2026-07-03-at-11-34-40_jpeg_jpg.rf.e44b00af0d7c1315755d82ddc9ed8c08.jpg | C514: Original do grupo (internet) | D514: Treino | E514: açaí, triatomíneo | F514: 1 | G514: 1 | U514: Recebida pelo WhatsApp do grupo; procurar a origem por busca reversa (Google Lens)
...

Sheet Resumo
A1: Resumo do banco final (547 imagens)
A3: Origem | B3: Treino | C3: Validação | D3: Teste | E3: Total | F3: Instâncias açaí | G3: Instâncias triatomíneo | H3: Imagens de fundo
A4: iNaturalist | B4: =COUNTIFS(Imagens!$C:$C,$A4,Imagens!$D:$D,"Treino") -> 333 | C4: =COUNTIFS(Imagens!$C:$C,$A4,Imagens!$D:$D,"Validação") -> 69 | D4: =COUNTIFS(Imagens!$C:$C,$A4,Imagens!$D:$D,"Teste") -> 70 | E4: =SUM(B4:D4) -> 472 | F4: =SUMIFS(Imagens!$F:$F,Imagens!$C:$C,$A4) -> 77 | G4: =SUMIFS(Imagens!$G:$G,Imagens!$C:$C,$A4) -> 351 | H4: =COUNTIFS(Imagens!$C:$C,$A4,Imagens!$E:$E,"Fundo (sem marcação)") -> 100
A5: Busca na internet (açaí) | B5: =COUNTIFS(Imagens!$C:$C,$A5,Imagens!$D:$D,"Treino") -> 21 | C5: =COUNTIFS(Imagens!$C:$C,$A5,Imagens!$D:$D,"Validação") -> 5 | D5: =COUNTIFS(Imagens!$C:$C,$A5,Imagens!$D:$D,"Teste") -> 3 | E5: =SUM(B5:D5) -> 29 | F5: =SUMIFS(Imagens!$F:$F,Imagens!$C:$C,$A5) -> 42 | G5: =SUMIFS(Imagens!$G:$G,Imagens!$C:$C,$A5) -> 0 | H5: =COUNTIFS(Imagens!$C:$C,$A5,Imagens!$E:$E,"Fundo (sem marcação)") -> 0
A6: Original do grupo (internet) | B6: =COUNTIFS(Imagens!$C:$C,$A6,Imagens!$D:$D,"Treino") -> 27 | C6: =COUNTIFS(Imagens!$C:$C,$A6,Imagens!$D:$D,"Validação") -> 7 | D6: =COUNTIFS(Imagens!$C:$C,$A6,Imagens!$D:$D,"Teste") -> 8 | E6: =SUM(B6:D6) -> 42 | F6: =SUMIFS(Imagens!$F:$F,Imagens!$C:$C,$A6) -> 31 | G6: =SUMIFS(Imagens!$G:$G,Imagens!$C:$C,$A6) -> 27 | H6: =COUNTIFS(Imagens!$C:$C,$A6,Imagens!$E:$E,"Fundo (sem marcação)") -> 0
A7: Gerada por IA (Gemini) | B7: =COUNTIFS(Imagens!$C:$C,$A7,Imagens!$D:$D,"Treino") -> 4 | C7: =COUNTIFS(Imagens!$C:$C,$A7,Imagens!$D:$D,"Validação") -> 0 | D7: =COUNTIFS(Imagens!$C:$C,$A7,Imagens!$D:$D,"Teste") -> 0 | E7: =SUM(B7:D7) -> 4 | F7: =SUMIFS(Imagens!$F:$F,Imagens!$C:$C,$A7) -> 1 | G7: =SUMIFS(Imagens!$G:$G,Imagens!$C:$C,$A7) -> 4 | H7: =COUNTIFS(Imagens!$C:$C,$A7,Imagens!$E:$E,"Fundo (sem marcação)") -> 0
A8: Total | B8: =SUM(B4:B7) -> 385 | C8: =SUM(C4:C7) -> 81 | D8: =SUM(D4:D7) -> 81 | E8: =SUM(E4:E7) -> 547 | F8: =SUM(F4:F7) -> 151 | G8: =SUM(G4:G7) -> 382 | H8: =SUM(H4:H7) -> 100
A10: Licenças (iNaturalist) | B10: Imagens
A11: CC0 | B11: =COUNTIFS(Imagens!$O:$O,A11) -> 23
A12: CC-BY | B12: =COUNTIFS(Imagens!$O:$O,A12) -> 84
A13: CC-BY-NC | B13: =COUNTIFS(Imagens!$O:$O,A13) -> 365
A15: Imagens da internet ainda sem link de origem | B15: =COUNTIFS(Imagens!$C:$C,"Busca na internet (açaí)",Imagens!$T:$T,"")+COUNTIFS(Imagens!$C:$C,"Original do grupo (internet)",Imagens!$T:$T,"") -> 70
